Workbook

Sheet Questions
A1: # | B1: LeetCode Problem | C1: Pattern | D1: Difficulty | E1: Category | F1: Link | G1: Blind 75 | H1: Also Applies | I1: Status | J1: Notes
A2: 1 | B2: Is Subsequence | C2: Two Pointers | D2: Easy | E2: Arrays | F2: Open | I2: Done | J2: Can be done using DP also
A3: 2 | B3: Squares of a Sorted Array | C3: Two Pointers | D3: Easy | E3: Arrays | F3: Open | I3: Not Started
A4: 3 | B4: String Compression | C4: Two Pointers | D4: Easy | E4: Strings | F4: Open | I4: Not Started
A5: 4 | B5: Two Sum | C5: Two Pointers | D5: Easy | E5: Arrays | F5: Open | G5: Yes | H5: Hash Maps | I5: Done | J5: Single pass, store what you've seen, query for the complement
A6: 5 | B6: Valid Palindrome | C6: Two Pointers | D6: Easy | E6: Strings | F6: Open | G6: Yes | I6: Not Started
A7: 6 | B7: 3Sum | C7: Two Pointers | D7: Medium | E7: Arrays | F7: Open | G7: Yes | I7: Not Started
A8: 7 | B8: Container With Most Water | C8: Two Pointers | D8: Medium | E8: - | F8: Open | G8: Yes | I8: Done
A9: 8 | B9: Intersection of Two Linked Lists | C9: Two Pointers | D9: Medium | E9: Linked Lists | F9: Open | I9: Not Started
A10: 9 | B10: Move Zeroes | C10: Two Pointers | D10: Medium | E10: Arrays | F10: Open | I10: Not Started
A11: 10 | B11: One Edit Distance | C11: Two Pointers | D11: Medium | E11: Strings | F11: Open | I11: Not Started
A12: 11 | B12: Remove Nth Node From End of List | C12: Two Pointers | D12: Medium | E12: Linked Lists | F12: Open | G12: Yes | I12: Done | J12: One pointer going first then another pointer following later
A13: 12 | B13: Reverse Words in a String | C13: Two Pointers | D13: Medium | E13: Strings | F13: Open | I13: Not Started
A14: 13 | B14: Sort Colors | C14: Two Pointers | D14: Medium | E14: Sorting | F14: Open | H14: Sort and Search | I14: Not Started
A15: 14 | B15: Linked List Cycle | C15: Fast and Slow Pointers | D15: Easy | E15: - | F15: Open | G15: Yes | I15: Done | J15: HashSet OR two pointers (Floyd's algo)
A16: 15 | B16: Middle of the Linked List | C16: Fast and Slow Pointers | D16: Easy | E16: Linked Lists | F16: Open | I16: Not Started
A17: 16 | B17: Linked List Cycle II | C17: Fast and Slow Pointers | D17: Hard | E17: Linked Lists | F17: Open | I17: Not Started
A18: 17 | B18: Palindrome Linked List | C18: Fast and Slow Pointers | D18: Very Hard | E18: Linked Lists | F18: Open | I18: Not Started
A19: 18 | B19: Longest Repeating Character Replacement | C19: Sliding Window | D19: Medium | E19: - | F19: Open | G19: Yes | I19: Not Started
A20: 19 | B20: Longest Substring Without Repeating Characters | C20: Sliding Window | D20: Hard | E20: Strings | F20: Open | G20: Yes | I20: Not Started
A21: 20 | B21: Maximum Size Subarray Sum Equals k | C21: Sliding Window | D21: Hard | E21: Arrays | F21: Open | I21: Not Started
A22: 21 | B22: Minimum Window Substring | C22: Sliding Window | D22: Very Hard | E22: Strings | F22: Open | G22: Yes | I22: Not Started
A23: 22 | B23: Meeting Rooms | C23: Intervals | D23: Easy | E23: - | F23: Open | G23: Yes | I23: Not Started
A24: 23 | B24: Insert Interval | C24: Intervals | D24: Medium | E24: - | F24: Open | G24: Yes | I24: Not Started
A25: 24 | B25: Merge Intervals | C25: Intervals | D25: Medium | E25: Arrays | F25: Open | G25: Yes | I25: Not Started
A26: 25 | B26: Non-overlapping Intervals | C26: Intervals | D26: Medium | E26: - | F26: Open | G26: Yes | I26: Not Started
A27: 26 | B27: Meeting Rooms II | C27: Intervals | D27: Hard | E27: Heaps | F27: Open | G27: Yes | H27: Top K Elements | I27: Not Started
A28: 27 | B28: Meeting Scheduler | C28: Intervals | D28: Very Hard | E28: Arrays | F28: Open | I28: Not Started
A29: 28 | B29: Remove Duplicates from Sorted List | C29: In-Place Manipulation of a Linked List | D29: Easy | E29: Linked Lists | F29: Open | I29: Not Started
A30: 29 | B30: Add Two Numbers | C30: In-Place Manipulation of a Linked List | D30: Medium | E30: Linked Lists | F30: Open | I30: Not Started
A31: 30 | B31: Merge Two Sorted Lists | C31: In-Place Manipulation of a Linked List | D31: Hard | E31: Linked Lists | F31: Open | G31: Yes | I31: Not Started
A32: 31 | B32: Reverse Linked List | C32: In-Place Manipulation of a Linked List | D32: Hard | E32: Linked Lists | F32: Open | G32: Yes | I32: Not Started
A33: 32 | B33: Rotate List | C33: In-Place Manipulation of a Linked List | D33: Hard | E33: Linked Lists | F33: Open | I33: Not Started
A34: 33 | B34: Partition List | C34: In-Place Manipulation of a Linked List | D34: Very Hard | E34: Linked Lists | F34: Open | I34: Not Started
A35: 34 | B35: Reorder List | C35: In-Place Manipulation of a Linked List | D35: Very Hard | E35: Linked Lists | F35: Open | G35: Yes | I35: Not Started
A36: 35 | B36: Swap Nodes in Pairs | C36: In-Place Manipulation of a Linked List | D36: Very Hard | E36: Linked Lists | F36: Open | I36: Not Started
A37: 36 | B37: Find Median from Data Stream | C37: Two Heaps | D37: Hard | E37: Heaps | F37: Open | G37: Yes | I37: Not Started
A38: 37 | B38: Merge k Sorted Lists | C38: K-way Merge | D38: Very Hard | E38: Heaps | F38: Open | G38: Yes | I38: Not Started
A39: 38 | B39: Kth Largest Element in an Array | C39: Top K Elements | D39: Medium | E39: Searching | F39: Open | I39: Not Started | J39: One LeetCode problem covering 2 AlgoExpert questions: Find Three Largest Numbers, Quickselect
A40: 39 | B40: Top K Frequent Elements | C40: Top K Elements | D40: Medium | E40: - | F40: Open | G40: Yes | I40: Not Started
...

Sheet By Pattern
A1: Pattern # | B1: LeetCode Problem | C1: Difficulty | D1: Category | E1: Link | F1: Blind 75 | G1: Status
A2: 1. Two Pointers - 13 problems (5 in the Blind 75)
A3: 1 | B3: Is Subsequence | C3: Easy | D3: Arrays | E3: Open | G3: Not Started
A4: 1 | B4: Squares of a Sorted Array | C4: Easy | D4: Arrays | E4: Open | G4: Not Started
A5: 1 | B5: String Compression | C5: Easy | D5: Strings | E5: Open | G5: Not Started
A6: 1 | B6: Two Sum | C6: Easy | D6: Arrays | E6: Open | F6: Yes | G6: Not Started
A7: 1 | B7: Valid Palindrome | C7: Easy | D7: Strings | E7: Open | F7: Yes | G7: Not Started
A8: 1 | B8: 3Sum | C8: Medium | D8: Arrays | E8: Open | F8: Yes | G8: Not Started
A9: 1 | B9: Container With Most Water | C9: Medium | D9: - | E9: Open | F9: Yes | G9: Not Started
A10: 1 | B10: Intersection of Two Linked Lists | C10: Medium | D10: Linked Lists | E10: Open | G10: Not Started
A11: 1 | B11: Move Zeroes | C11: Medium | D11: Arrays | E11: Open | G11: Not Started
A12: 1 | B12: One Edit Distance | C12: Medium | D12: Strings | E12: Open | G12: Not Started
A13: 1 | B13: Remove Nth Node From End of List | C13: Medium | D13: Linked Lists | E13: Open | F13: Yes | G13: Not Started
A14: 1 | B14: Reverse Words in a String | C14: Medium | D14: Strings | E14: Open | G14: Not Started
A15: 1 | B15: Sort Colors | C15: Medium | D15: Sorting | E15: Open | G15: Not Started
A16: 2. Fast and Slow Pointers - 4 problems (1 in the Blind 75)
A17: 2 | B17: Linked List Cycle | C17: Easy | D17: - | E17: Open | F17: Yes | G17: Not Started
A18: 2 | B18: Middle of the Linked List | C18: Easy | D18: Linked Lists | E18: Open | G18: Not Started
A19: 2 | B19: Linked List Cycle II | C19: Hard | D19: Linked Lists | E19: Open | G19: Not Started
A20: 2 | B20: Palindrome Linked List | C20: Very Hard | D20: Linked Lists | E20: Open | G20: Not Started
A21: 3. Sliding Window - 4 problems (3 in the Blind 75)
A22: 3 | B22: Longest Repeating Character Replacement | C22: Medium | D22: - | E22: Open | F22: Yes | G22: Not Started
A23: 3 | B23: Longest Substring Without Repeating Characters | C23: Hard | D23: Strings | E23: Open | F23: Yes | G23: Not Started
A24: 3 | B24: Maximum Size Subarray Sum Equals k | C24: Hard | D24: Arrays | E24: Open | G24: Not Started
A25: 3 | B25: Minimum Window Substring | C25: Very Hard | D25: Strings | E25: Open | F25: Yes | G25: Not Started
A26: 4. Intervals - 6 problems (5 in the Blind 75)
A27: 4 | B27: Meeting Rooms | C27: Easy | D27: - | E27: Open | F27: Yes | G27: Not Started
A28: 4 | B28: Insert Interval | C28: Medium | D28: - | E28: Open | F28: Yes | G28: Not Started
A29: 4 | B29: Merge Intervals | C29: Medium | D29: Arrays | E29: Open | F29: Yes | G29: Not Started
A30: 4 | B30: Non-overlapping Intervals | C30: Medium | D30: - | E30: Open | F30: Yes | G30: Not Started
A31: 4 | B31: Meeting Rooms II | C31: Hard | D31: Heaps | E31: Open | F31: Yes | G31: Not Started
A32: 4 | B32: Meeting Scheduler | C32: Very Hard | D32: Arrays | E32: Open | G32: Not Started
A33: 5. In-Place Manipulation of a Linked List - 8 problems (3 in the Blind 75)
A34: 5 | B34: Remove Duplicates from Sorted List | C34: Easy | D34: Linked Lists | E34: Open | G34: Not Started
A35: 5 | B35: Add Two Numbers | C35: Medium | D35: Linked Lists | E35: Open | G35: Not Started
A36: 5 | B36: Merge Two Sorted Lists | C36: Hard | D36: Linked Lists | E36: Open | F36: Yes | G36: Not Started
A37: 5 | B37: Reverse Linked List | C37: Hard | D37: Linked Lists | E37: Open | F37: Yes | G37: Not Started
A38: 5 | B38: Rotate List | C38: Hard | D38: Linked Lists | E38: Open | G38: Not Started
A39: 5 | B39: Partition List | C39: Very Hard | D39: Linked Lists | E39: Open | G39: Not Started
A40: 5 | B40: Reorder List | C40: Very Hard | D40: Linked Lists | E40: Open | F40: Yes | G40: Not Started
...

Sheet Blind 75 Overlap
A1: Blind 75 - all 75 present in this workbook
A3: # | B3: Blind 75 Problem | C3: Link | D3: In AlgoExpert 200? | E3: AlgoExpert Question(s) | F3: Match
A4: 1 | B4: Two Sum | C4: Open | D4: Yes | E4: Two Number Sum | F4: Direct
A5: 2 | B5: Contains Duplicate | C5: Open | D5: Added separately | E5: - | F5: -
A6: 3 | B6: Top K Frequent Elements | C6: Open | D6: Added separately | E6: - | F6: -
A7: 4 | B7: Product of Array Except Self | C7: Open | D7: Yes | E7: Array Of Products | F7: Direct
A8: 5 | B8: Longest Consecutive Sequence | C8: Open | D8: Yes | E8: Largest Range | F8: Direct
A9: 6 | B9: 3Sum | C9: Open | D9: Yes | E9: Three Number Sum | F9: Direct
A10: 7 | B10: Container With Most Water | C10: Open | D10: Added separately | E10: - | F10: -
A11: 8 | B11: Best Time to Buy and Sell Stock | C11: Open | D11: Added separately | E11: - | F11: -
A12: 9 | B12: Combination Sum | C12: Open | D12: Added separately | E12: - | F12: -
A13: 10 | B13: Insert Interval | C13: Open | D13: Added separately | E13: - | F13: -
A14: 11 | B14: Merge Intervals | C14: Open | D14: Yes | E14: Merge Overlapping Intervals | F14: Direct
A15: 12 | B15: Non-overlapping Intervals | C15: Open | D15: Added separately | E15: - | F15: -
... A78: 75 | B78: Sum of Two Integers | C78: Open | D78: Added separately | E78: - | F78: -
B79: 38 of 75 already in the AlgoExpert 200 | 37 added as extra rows | 75 of 75 now in this workbook
A81: Rows marked 'Added separately' now sit inside their own pattern section on the Questions and By Pattern tabs, with Source = 'Blind 75 gap'. Several are already drilled via a harder AlgoExpert sibling - the Notes column says which, so you can deprioritise those.

Sheet Pattern Coverage
A1: The 28 Grokking patterns - deduplicated list, one record per LeetCode problem
A3: # | B3: Grokking Pattern | C3: Easy | D3: Medium | E3: Hard | F3: Very Hard | G3: Total | H3: In Blind 75 | I3: Coverage
A4: 1 | B4: Two Pointers | C4: =COUNTIFS(Questions!$C$2:$C$199,$B4,Questions!$D$2:$D$199,C$3) -> 5 | D4: =COUNTIFS(Questions!$C$2:$C$199,$B4,Questions!$D$2:$D$199,D$3) -> 8 | E4: =COUNTIFS(Questions!$C$2:$C$199,$B4,Questions!$D$2:$D$199,E$3) -> 0 | F4: =COUNTIFS(Questions!$C$2:$C$199,$B4,Questions!$D$2:$D$199,F$3) -> 0 | G4: =COUNTIF(Questions!$C$2:$C$199,$B4) -> 13 | H4: =COUNTIFS(Questions!$C$2:$C$199,$B4,Questions!$G$2:$G$199,"Yes") -> 5 | I4: =IF($G4=0,"GAP",IF($G4<=2,"Thin","Covered")) -> Covered
A5: 2 | B5: Fast and Slow Pointers | C5: =COUNTIFS(Questions!$C$2:$C$199,$B5,Questions!$D$2:$D$199,C$3) -> 2 | D5: =COUNTIFS(Questions!$C$2:$C$199,$B5,Questions!$D$2:$D$199,D$3) -> 0 | E5: =COUNTIFS(Questions!$C$2:$C$199,$B5,Questions!$D$2:$D$199,E$3) -> 1 | F5: =COUNTIFS(Questions!$C$2:$C$199,$B5,Questions!$D$2:$D$199,F$3) -> 1 | G5: =COUNTIF(Questions!$C$2:$C$199,$B5) -> 4 | H5: =COUNTIFS(Questions!$C$2:$C$199,$B5,Questions!$G$2:$G$199,"Yes") -> 1 | I5: =IF($G5=0,"GAP",IF($G5<=2,"Thin","Covered")) -> Covered
A6: 3 | B6: Sliding Window | C6: =COUNTIFS(Questions!$C$2:$C$199,$B6,Questions!$D$2:$D$199,C$3) -> 0 | D6: =COUNTIFS(Questions!$C$2:$C$199,$B6,Questions!$D$2:$D$199,D$3) -> 1 | E6: =COUNTIFS(Questions!$C$2:$C$199,$B6,Questions!$D$2:$D$199,E$3) -> 2 | F6: =COUNTIFS(Questions!$C$2:$C$199,$B6,Questions!$D$2:$D$199,F$3) -> 1 | G6: =COUNTIF(Questions!$C$2:$C$199,$B6) -> 4 | H6: =COUNTIFS(Questions!$C$2:$C$199,$B6,Questions!$G$2:$G$199,"Yes") -> 3 | I6: =IF($G6=0,"GAP",IF($G6<=2,"Thin","Covered")) -> Covered
A7: 4 | B7: Intervals | C7: =COUNTIFS(Questions!$C$2:$C$199,$B7,Questions!$D$2:$D$199,C$3) -> 1 | D7: =COUNTIFS(Questions!$C$2:$C$199,$B7,Questions!$D$2:$D$199,D$3) -> 3 | E7: =COUNTIFS(Questions!$C$2:$C$199,$B7,Questions!$D$2:$D$199,E$3) -> 1 | F7: =COUNTIFS(Questions!$C$2:$C$199,$B7,Questions!$D$2:$D$199,F$3) -> 1 | G7: =COUNTIF(Questions!$C$2:$C$199,$B7) -> 6 | H7: =COUNTIFS(Questions!$C$2:$C$199,$B7,Questions!$G$2:$G$199,"Yes") -> 5 | I7: =IF($G7=0,"GAP",IF($G7<=2,"Thin","Covered")) -> Covered
A8: 5 | B8: In-Place Manipulation of a Linked List | C8: =COUNTIFS(Questions!$C$2:$C$199,$B8,Questions!$D$2:$D$199,C$3) -> 1 | D8: =COUNTIFS(Questions!$C$2:$C$199,$B8,Questions!$D$2:$D$199,D$3) -> 1 | E8: =COUNTIFS(Questions!$C$2:$C$199,$B8,Questions!$D$2:$D$199,E$3) -> 3 | F8: =COUNTIFS(Questions!$C$2:$C$199,$B8,Questions!$D$2:$D$199,F$3) -> 3 | G8: =COUNTIF(Questions!$C$2:$C$199,$B8) -> 8 | H8: =COUNTIFS(Questions!$C$2:$C$199,$B8,Questions!$G$2:$G$199,"Yes") -> 3 | I8: =IF($G8=0,"GAP",IF($G8<=2,"Thin","Covered")) -> Covered
A9: 6 | B9: Two Heaps | C9: =COUNTIFS(Questions!$C$2:$C$199,$B9,Questions!$D$2:$D$199,C$3) -> 0 | D9: =COUNTIFS(Questions!$C$2:$C$199,$B9,Questions!$D$2:$D$199,D$3) -> 0 | E9: =COUNTIFS(Questions!$C$2:$C$199,$B9,Questions!$D$2:$D$199,E$3) -> 1 | F9: =COUNTIFS(Questions!$C$2:$C$199,$B9,Questions!$D$2:$D$199,F$3) -> 0 | G9: =COUNTIF(Questions!$C$2:$C$199,$B9) -> 1 | H9: =COUNTIFS(Questions!$C$2:$C$199,$B9,Questions!$G$2:$G$199,"Yes") -> 1 | I9: =IF($G9=0,"GAP",IF($G9<=2,"Thin","Covered")) -> Thin
A10: 7 | B10: K-way Merge | C10: =COUNTIFS(Questions!$C$2:$C$199,$B10,Questions!$D$2:$D$199,C$3) -> 0 | D10: =COUNTIFS(Questions!$C$2:$C$199,$B10,Questions!$D$2:$D$199,D$3) -> 0 | E10: =COUNTIFS(Questions!$C$2:$C$199,$B10,Questions!$D$2:$D$199,E$3) -> 0 | F10: =COUNTIFS(Questions!$C$2:$C$199,$B10,Questions!$D$2:$D$199,F$3) -> 1 | G10: =COUNTIF(Questions!$C$2:$C$199,$B10) -> 1 | H10: =COUNTIFS(Questions!$C$2:$C$199,$B10,Questions!$G$2:$G$199,"Yes") -> 1 | I10: =IF($G10=0,"GAP",IF($G10<=2,"Thin","Covered")) -> Thin
A11: 8 | B11: Top K Elements | C11: =COUNTIFS(Questions!$C$2:$C$199,$B11,Questions!$D$2:$D$199,C$3) -> 0 | D11: =COUNTIFS(Questions!$C$2:$C$199,$B11,Questions!$D$2:$D$199,D$3) -> 2 | E11: =COUNTIFS(Questions!$C$2:$C$199,$B11,Questions!$D$2:$D$199,E$3) -> 0 | F11: =COUNTIFS(Questions!$C$2:$C$199,$B11,Questions!$D$2:$D$199,F$3) -> 0 | G11: =COUNTIF(Questions!$C$2:$C$199,$B11) -> 2 | H11: =COUNTIFS(Questions!$C$2:$C$199,$B11,Questions!$G$2:$G$199,"Yes") -> 1 | I11: =IF($G11=0,"GAP",IF($G11<=2,"Thin","Covered")) -> Thin
A12: 9 | B12: Modified Binary Search | C12: =COUNTIFS(Questions!$C$2:$C$199,$B12,Questions!$D$2:$D$199,C$3) -> 2 | D12: =COUNTIFS(Questions!$C$2:$C$199,$B12,Questions!$D$2:$D$199,D$3) -> 1 | E12: =COUNTIFS(Questions!$C$2:$C$199,$B12,Questions!$D$2:$D$199,E$3) -> 3 | F12: =COUNTIFS(Questions!$C$2:$C$199,$B12,Questions!$D$2:$D$199,F$3) -> 2 | G12: =COUNTIF(Questions!$C$2:$C$199,$B12) -> 8 | H12: =COUNTIFS(Questions!$C$2:$C$199,$B12,Questions!$G$2:$G$199,"Yes") -> 2 | I12: =IF($G12=0,"GAP",IF($G12<=2,"Thin","Covered")) -> Covered
A13: 10 | B13: Subsets | C13: =COUNTIFS(Questions!$C$2:$C$199,$B13,Questions!$D$2:$D$199,C$3) -> 0 | D13: =COUNTIFS(Questions!$C$2:$C$199,$B13,Questions!$D$2:$D$199,D$3) -> 2 | E13: =COUNTIFS(Questions!$C$2:$C$199,$B13,Questions!$D$2:$D$199,E$3) -> 0 | F13: =COUNTIFS(Questions!$C$2:$C$199,$B13,Questions!$D$2:$D$199,F$3) -> 0 | G13: =COUNTIF(Questions!$C$2:$C$199,$B13) -> 2 | H13: =COUNTIFS(Questions!$C$2:$C$199,$B13,Questions!$G$2:$G$199,"Yes") -> 0 | I13: =IF($G13=0,"GAP",IF($G13<=2,"Thin","Covered")) -> Thin
A14: 11 | B14: Greedy Techniques | C14: =COUNTIFS(Questions!$C$2:$C$199,$B14,Questions!$D$2:$D$199,C$3) -> 0 | D14: =COUNTIFS(Questions!$C$2:$C$199,$B14,Questions!$D$2:$D$199,D$3) -> 3 | E14: =COUNTIFS(Questions!$C$2:$C$199,$B14,Questions!$D$2:$D$199,E$3) -> 1 | F14: =COUNTIFS(Questions!$C$2:$C$199,$B14,Questions!$D$2:$D$199,F$3) -> 0 | G14: =COUNTIF(Questions!$C$2:$C$199,$B14) -> 4 | H14: =COUNTIFS(Questions!$C$2:$C$199,$B14,Questions!$G$2:$G$199,"Yes") -> 1 | I14: =IF($G14=0,"GAP",IF($G14<=2,"Thin","Covered")) -> Covered
A15: 12 | B15: Backtracking | C15: =COUNTIFS(Questions!$C$2:$C$199,$B15,Questions!$D$2:$D$199,C$3) -> 0 | D15: =COUNTIFS(Questions!$C$2:$C$199,$B15,Questions!$D$2:$D$199,D$3) -> 4 | E15: =COUNTIFS(Questions!$C$2:$C$199,$B15,Questions!$D$2:$D$199,E$3) -> 3 | F15: =COUNTIFS(Questions!$C$2:$C$199,$B15,Questions!$D$2:$D$199,F$3) -> 1 | G15: =COUNTIF(Questions!$C$2:$C$199,$B15) -> 8 | H15: =COUNTIFS(Questions!$C$2:$C$199,$B15,Questions!$G$2:$G$199,"Yes") -> 3 | I15: =IF($G15=0,"GAP",IF($G15<=2,"Thin","Covered")) -> Covered
... A31: 28 | B31: Math and Geometry | C31: =COUNTIFS(Questions!$C$2:$C$199,$B31,Questions!$D$2:$D$199,C$3) -> 1 | D31: =COUNTIFS(Questions!$C$2:$C$199,$B31,Questions!$D$2:$D$199,D$3) -> 0 | E31: =COUNTIFS(Questions!$C$2:$C$199,$B31,Questions!$D$2:$D$199,E$3) -> 1 | F31: =COUNTIFS(Questions!$C$2:$C$199,$B31,Questions!$D$2:$D$199,F$3) -> 2 | G31: =COUNTIF(Questions!$C$2:$C$199,$B31) -> 4 | H31: =COUNTIFS(Questions!$C$2:$C$199,$B31,Questions!$G$2:$G$199,"Yes") -> 0 | I31: =IF($G31=0,"GAP",IF($G31<=2,"Thin","Covered")) -> Covered
B32: Total | C32: =SUM(C4:C31) -> 32 | D32: =SUM(D4:D31) -> 94 | E32: =SUM(E4:E31) -> 45 | F32: =SUM(F4:F31) -> 27 | G32: =SUM(G4:G31) -> 198 | H32: =SUM(H4:H31) -> 75

Sheet By Category
A1: AlgoExpert's own categories (blank/'-' rows are the Blind 75 additions)
A3: Category | B3: Easy | C3: Medium | D3: Hard | E3: Very Hard | F3: Total
A4: Arrays | B4: =COUNTIFS(Questions!$E$2:$E$199,"*"&$A4&"*",Questions!$D$2:$D$199,B$3) -> 4 | C4: =COUNTIFS(Questions!$E$2:$E$199,"*"&$A4&"*",Questions!$D$2:$D$199,C$3) -> 12 | D4: =COUNTIFS(Questions!$E$2:$E$199,"*"&$A4&"*",Questions!$D$2:$D$199,D$3) -> 8 | E4: =COUNTIFS(Questions!$E$2:$E$199,"*"&$A4&"*",Questions!$D$2:$D$199,E$3) -> 3 | F4: =COUNTIF(Questions!$E$2:$E$199,"*"&$A4&"*") -> 27
A5: Binary Search Trees | B5: =COUNTIFS(Questions!$E$2:$E$199,"*"&$A5&"*",Questions!$D$2:$D$199,B$3) -> 2 | C5: =COUNTIFS(Questions!$E$2:$E$199,"*"&$A5&"*",Questions!$D$2:$D$199,C$3) -> 5 | D5: =COUNTIFS(Questions!$E$2:$E$199,"*"&$A5&"*",Questions!$D$2:$D$199,D$3) -> 3 | E5: =COUNTIFS(Questions!$E$2:$E$199,"*"&$A5&"*",Questions!$D$2:$D$199,E$3) -> 0 | F5: =COUNTIF(Questions!$E$2:$E$199,"*"&$A5&"*") -> 10
A6: Binary Trees | B6: =COUNTIFS(Questions!$E$2:$E$199,"*"&$A6&"*",Questions!$D$2:$D$199,B$3) -> 4 | C6: =COUNTIFS(Questions!$E$2:$E$199,"*"&$A6&"*",Questions!$D$2:$D$199,C$3) -> 7 | D6: =COUNTIFS(Questions!$E$2:$E$199,"*"&$A6&"*",Questions!$D$2:$D$199,D$3) -> 2 | E6: =COUNTIFS(Questions!$E$2:$E$199,"*"&$A6&"*",Questions!$D$2:$D$199,E$3) -> 3 | F6: =COUNTIF(Questions!$E$2:$E$199,"*"&$A6&"*") -> 16
A7: Dynamic Programming | B7: =COUNTIFS(Questions!$E$2:$E$199,"*"&$A7&"*",Questions!$D$2:$D$199,B$3) -> 0 | C7: =COUNTIFS(Questions!$E$2:$E$199,"*"&$A7&"*",Questions!$D$2:$D$199,C$3) -> 5 | D7: =COUNTIFS(Questions!$E$2:$E$199,"*"&$A7&"*",Questions!$D$2:$D$199,D$3) -> 8 | E7: =COUNTIFS(Questions!$E$2:$E$199,"*"&$A7&"*",Questions!$D$2:$D$199,E$3) -> 5 | F7: =COUNTIF(Questions!$E$2:$E$199,"*"&$A7&"*") -> 18
A8: Famous Algorithms | B8: =COUNTIFS(Questions!$E$2:$E$199,"*"&$A8&"*",Questions!$D$2:$D$199,B$3) -> 0 | C8: =COUNTIFS(Questions!$E$2:$E$199,"*"&$A8&"*",Questions!$D$2:$D$199,C$3) -> 3 | D8: =COUNTIFS(Questions!$E$2:$E$199,"*"&$A8&"*",Questions!$D$2:$D$199,D$3) -> 2 | E8: =COUNTIFS(Questions!$E$2:$E$199,"*"&$A8&"*",Questions!$D$2:$D$199,E$3) -> 2 | F8: =COUNTIF(Questions!$E$2:$E$199,"*"&$A8&"*") -> 7
A9: Graphs | B9: =COUNTIFS(Questions!$E$2:$E$199,"*"&$A9&"*",Questions!$D$2:$D$199,B$3) -> 1 | C9: =COUNTIFS(Questions!$E$2:$E$199,"*"&$A9&"*",Questions!$D$2:$D$199,C$3) -> 7 | D9: =COUNTIFS(Questions!$E$2:$E$199,"*"&$A9&"*",Questions!$D$2:$D$199,D$3) -> 2 | E9: =COUNTIFS(Questions!$E$2:$E$199,"*"&$A9&"*",Questions!$D$2:$D$199,E$3) -> 1 | F9: =COUNTIF(Questions!$E$2:$E$199,"*"&$A9&"*") -> 11
A10: Greedy Algorithms | B10: =COUNTIFS(Questions!$E$2:$E$199,"*"&$A10&"*",Questions!$D$2:$D$199,B$3) -> 0 | C10: =COUNTIFS(Questions!$E$2:$E$199,"*"&$A10&"*",Questions!$D$2:$D$199,C$3) -> 2 | D10: =COUNTIFS(Questions!$E$2:$E$199,"*"&$A10&"*",Questions!$D$2:$D$199,D$3) -> 0 | E10: =COUNTIFS(Questions!$E$2:$E$199,"*"&$A10&"*",Questions!$D$2:$D$199,E$3) -> 0 | F10: =COUNTIF(Questions!$E$2:$E$199,"*"&$A10&"*") -> 2
A11: Heaps | B11: =COUNTIFS(Questions!$E$2:$E$199,"*"&$A11&"*",Questions!$D$2:$D$199,B$3) -> 0 | C11: =COUNTIFS(Questions!$E$2:$E$199,"*"&$A11&"*",Questions!$D$2:$D$199,C$3) -> 1 | D11: =COUNTIFS(Questions!$E$2:$E$199,"*"&$A11&"*",Questions!$D$2:$D$199,D$3) -> 2 | E11: =COUNTIFS(Questions!$E$2:$E$199,"*"&$A11&"*",Questions!$D$2:$D$199,E$3) -> 1 | F11: =COUNTIF(Questions!$E$2:$E$199,"*"&$A11&"*") -> 4
A12: Linked Lists | B12: =COUNTIFS(Questions!$E$2:$E$199,"*"&$A12&"*",Questions!$D$2:$D$199,B$3) -> 2 | C12: =COUNTIFS(Questions!$E$2:$E$199,"*"&$A12&"*",Questions!$D$2:$D$199,C$3) -> 4 | D12: =COUNTIFS(Questions!$E$2:$E$199,"*"&$A12&"*",Questions!$D$2:$D$199,D$3) -> 4 | E12: =COUNTIFS(Questions!$E$2:$E$199,"*"&$A12&"*",Questions!$D$2:$D$199,E$3) -> 5 | F12: =COUNTIF(Questions!$E$2:$E$199,"*"&$A12&"*") -> 15
A13: Recursion | B13: =COUNTIFS(Questions!$E$2:$E$199,"*"&$A13&"*",Questions!$D$2:$D$199,B$3) -> 2 | C13: =COUNTIFS(Questions!$E$2:$E$199,"*"&$A13&"*",Questions!$D$2:$D$199,C$3) -> 7 | D13: =COUNTIFS(Questions!$E$2:$E$199,"*"&$A13&"*",Questions!$D$2:$D$199,D$3) -> 3 | E13: =COUNTIFS(Questions!$E$2:$E$199,"*"&$A13&"*",Questions!$D$2:$D$199,E$3) -> 2 | F13: =COUNTIF(Questions!$E$2:$E$199,"*"&$A13&"*") -> 14
A14: Searching | B14: =COUNTIFS(Questions!$E$2:$E$199,"*"&$A14&"*",Questions!$D$2:$D$199,B$3) -> 1 | C14: =COUNTIFS(Questions!$E$2:$E$199,"*"&$A14&"*",Questions!$D$2:$D$199,C$3) -> 2 | D14: =COUNTIFS(Questions!$E$2:$E$199,"*"&$A14&"*",Questions!$D$2:$D$199,D$3) -> 3 | E14: =COUNTIFS(Questions!$E$2:$E$199,"*"&$A14&"*",Questions!$D$2:$D$199,E$3) -> 2 | F14: =COUNTIF(Questions!$E$2:$E$199,"*"&$A14&"*") -> 8
A15: Sorting | B15: =COUNTIFS(Questions!$E$2:$E$199,"*"&$A15&"*",Questions!$D$2:$D$199,B$3) -> 0 | C15: =COUNTIFS(Questions!$E$2:$E$199,"*"&$A15&"*",Questions!$D$2:$D$199,C$3) -> 2 | D15: =COUNTIFS(Questions!$E$2:$E$199,"*"&$A15&"*",Questions!$D$2:$D$199,D$3) -> 1 | E15: =COUNTIFS(Questions!$E$2:$E$199,"*"&$A15&"*",Questions!$D$2:$D$199,E$3) -> 0 | F15: =COUNTIF(Questions!$E$2:$E$199,"*"&$A15&"*") -> 3
... A18: Tries | B18: =COUNTIFS(Questions!$E$2:$E$199,"*"&$A18&"*",Questions!$D$2:$D$199,B$3) -> 0 | C18: =COUNTIFS(Questions!$E$2:$E$199,"*"&$A18&"*",Questions!$D$2:$D$199,C$3) -> 1 | D18: =COUNTIFS(Questions!$E$2:$E$199,"*"&$A18&"*",Questions!$D$2:$D$199,D$3) -> 2 | E18: =COUNTIFS(Questions!$E$2:$E$199,"*"&$A18&"*",Questions!$D$2:$D$199,E$3) -> 0 | F18: =COUNTIF(Questions!$E$2:$E$199,"*"&$A18&"*") -> 3
A19: Blind 75 additions | B19: =COUNTIFS(Questions!$E$2:$E$199,"-",Questions!$D$2:$D$199,B$3) -> 11 | C19: =COUNTIFS(Questions!$E$2:$E$199,"-",Questions!$D$2:$D$199,C$3) -> 24 | D19: =COUNTIFS(Questions!$E$2:$E$199,"-",Questions!$D$2:$D$199,D$3) -> 2 | E19: =COUNTIFS(Questions!$E$2:$E$199,"-",Questions!$D$2:$D$199,E$3) -> 0 | F19: =COUNTIF(Questions!$E$2:$E$199,"-") -> 37
A20: Total | B20: =SUM(B4:B19) -> 33 | C20: =SUM(C4:C19) -> 95 | D20: =SUM(D4:D19) -> 46 | E20: =SUM(E4:E19) -> 27 | F20: =SUM(F4:F19) -> 201
A22: Counts use a contains-match, because three merged rows carry two AlgoExpert categories. The column therefore double-counts those three, and will total slightly above the row count.

Sheet FAANG Extras
A1: FAANG Top 200 - the 72 problems not already on the Questions tab
A2: Kept separate from the main list on purpose. Nothing here is merged into Questions. Sorted by topic bucket, then by FAANG frequency.
A4: # | B4: LC # | C4: Problem | D4: Difficulty | E4: Topic / Pattern | F4: Frequency | G4: Companies | H4: Link | I4: Variant of (already in our list) | J4: Status | K4: Notes
A5: 1 | B5: 442 | C5: Find All Duplicates in an Array | D5: Medium | E5: Arrays & Hashing | F5: ★★★★ | G5: Amazon, Google | H5: Open | I5: Find the Duplicate Number | J5: Not Started | K5: Their file labels this "Find All Duplicates in Array"; the actual LeetCode title is "Find All Duplicates in an Array".
A6: 2 | B6: 189 | C6: Rotate Array | D6: Medium | E6: Arrays & Hashing | F6: ★★★★ | G6: Amazon, Microsoft | H6: Open | J6: Not Started
A7: 3 | B7: 31 | C7: Next Permutation | D7: Medium | E7: Arrays | F7: ★★★★ | G7: Google, Microsoft, Amazon | H7: Open | J7: Not Started
A8: 4 | B8: 167 | C8: Two Sum II – Input Array Is Sorted | D8: Medium | E8: Two Pointers | F8: ★★★★ | G8: Amazon, Apple | H8: Open | I8: Two Sum | J8: Not Started
A9: 5 | B9: 26 | C9: Remove Duplicates from Sorted Array | D9: Easy | E9: Two Pointers | F9: ★★★ | G9: Amazon, Microsoft | H9: Open | I9: Remove Duplicates from Sorted List | J9: Not Started
A10: 6 | B10: 239 | C10: Sliding Window Maximum | D10: Hard | E10: Sliding Window / Deque | F10: ★★★★★ | G10: Amazon, Google | H10: Open | J10: Not Started
A11: 7 | B11: 438 | C11: Find All Anagrams in a String | D11: Medium | E11: Sliding Window | F11: ★★★★ | G11: Amazon, Facebook | H11: Open | J11: Not Started
A12: 8 | B12: 904 | C12: Fruit Into Baskets | D12: Medium | E12: Sliding Window | F12: ★★★★ | G12: Amazon, Google | H12: Open | J12: Not Started
A13: 9 | B13: 209 | C13: Minimum Size Subarray Sum | D13: Medium | E13: Sliding Window | F13: ★★★★ | G13: Amazon, Google | H13: Open | I13: Maximum Size Subarray Sum Equals k | J13: Not Started
A14: 10 | B14: 567 | C14: Permutation in String | D14: Medium | E14: Sliding Window | F14: ★★★★ | G14: Amazon, Google, Meta | H14: Open | J14: Not Started
A15: 11 | B15: 853 | C15: Car Fleet | D15: Medium | E15: Stack / Monotonic | F15: ★★★★ | G15: Google | H15: Open | J15: Not Started
A16: 12 | B16: 739 | C16: Daily Temperatures | D16: Medium | E16: Stack / Monotonic | F16: ★★★★ | G16: Amazon, Google | H16: Open | J16: Not Started
A17: 13 | B17: 394 | C17: Decode String | D17: Medium | E17: Stack | F17: ★★★★ | G17: Google, Amazon | H17: Open | J17: Not Started
A18: 14 | B18: 162 | C18: Find Peak Element | D18: Medium | E18: Binary Search | F18: ★★★★ | G18: Google, Microsoft, Amazon | H18: Open | J18: Not Started
A19: 15 | B19: 875 | C19: Koko Eating Bananas | D19: Medium | E19: Binary Search | F19: ★★★★ | G19: Amazon, Google | H19: Open | J19: Not Started
A20: 16 | B20: 74 | C20: Search a 2D Matrix | D20: Medium | E20: Binary Search | F20: ★★★★ | G20: Amazon, Microsoft | H20: Open | I20: Search a 2D Matrix II | J20: Not Started
A21: 17 | B21: 81 | C21: Search in Rotated Sorted Array II | D21: Medium | E21: Binary Search | F21: ★★★★ | G21: Amazon, Microsoft | H21: Open | I21: Search in Rotated Sorted Array | J21: Not Started
A22: 18 | B22: 981 | C22: Time Based Key-Value Store | D22: Medium | E22: Binary Search | F22: ★★★★ | G22: Amazon, Google | H22: Open | J22: Not Started | K22: LeetCode Premium.
A23: 19 | B23: 278 | C23: First Bad Version | D23: Easy | E23: Binary Search | F23: ★★★ | G23: Amazon, Facebook | H23: Open | J23: Not Started
A24: 20 | B24: 25 | C24: Reverse Nodes in K-Group | D24: Hard | E24: Linked List | F24: ★★★★★ | G24: Amazon, Google | H24: Open | J24: Not Started
A25: 21 | B25: 138 | C25: Copy List with Random Pointer | D25: Medium | E25: Linked List | F25: ★★★★ | G25: Amazon, Microsoft | H25: Open | J25: Not Started
A26: 22 | B26: 148 | C26: Sort List | D26: Medium | E26: Linked List / Merge Sort | F26: ★★★★ | G26: Amazon, Google | H26: Open | I26: Sort an Array | J26: Not Started
A27: 23 | B27: 199 | C27: Binary Tree Right Side View | D27: Medium | E27: Trees / BFS | F27: ★★★★ | G27: Amazon, Facebook | H27: Open | J27: Not Started
A28: 24 | B28: 1448 | C28: Count Good Nodes in Binary Tree | D28: Medium | E28: Trees / DFS | F28: ★★★★ | G28: Google, Amazon | H28: Open | J28: Not Started
A29: 25 | B29: 114 | C29: Flatten Binary Tree to Linked List | D29: Medium | E29: Trees / DFS | F29: ★★★★ | G29: Amazon, Microsoft | H29: Open | I29: Convert Binary Search Tree to Sorted Doubly Linked List | J29: Not Started
A30: 26 | B30: 113 | C30: Path Sum II | D30: Medium | E30: Trees / DFS | F30: ★★★★ | G30: Amazon, Microsoft | H30: Open | I30: Binary Tree Paths | J30: Not Started
A31: 27 | B31: 502 | C31: IPO | D31: Hard | E31: Heap / Greedy | F31: ★★★★★ | G31: Amazon | H31: Open | J31: Not Started
A32: 28 | B32: 355 | C32: Design Twitter | D32: Medium | E32: Heap / HashMap | F32: ★★★★ | G32: Amazon, Google | H32: Open | J32: Not Started
A33: 29 | B33: 973 | C33: K Closest Points to Origin | D33: Medium | E33: Heap | F33: ★★★★ | G33: Amazon, Google, Facebook | H33: Open | J33: Not Started
A34: 30 | B34: 621 | C34: Task Scheduler | D34: Medium | E34: Heap / Greedy | F34: ★★★★ | G34: Amazon, Google, Meta | H34: Open | J34: Not Started
A35: 31 | B35: 1046 | C35: Last Stone Weight | D35: Easy | E35: Heap | F35: ★★★ | G35: Amazon, Google | H35: Open | J35: Not Started
A36: 32 | B36: 40 | C36: Combination Sum II | D36: Medium | E36: Backtracking | F36: ★★★★ | G36: Amazon, Microsoft | H36: Open | I36: Combination Sum | J36: Not Started
A37: 33 | B37: 131 | C37: Palindrome Partitioning | D37: Medium | E37: Backtracking / DP | F37: ★★★★ | G37: Amazon, Google | H37: Open | I37: Palindrome Partitioning II | J37: Not Started
A38: 34 | B38: 90 | C38: Subsets II | D38: Medium | E38: Backtracking | F38: ★★★★ | G38: Amazon, Microsoft | H38: Open | I38: Subsets | J38: Not Started
A39: 35 | B39: 332 | C39: Reconstruct Itinerary | D39: Hard | E39: Graphs / Euler Path | F39: ★★★★★ | G39: Google, Amazon | H39: Open | J39: Not Started
A40: 36 | B40: 778 | C40: Swim in Rising Water | D40: Hard | E40: Graphs / Dijkstra | F40: ★★★★★ | G40: Google | H40: Open | J40: Not Started
A41: 37 | B41: 127 | C41: Word Ladder | D41: Hard | E41: Graphs / BFS | F41: ★★★★★ | G41: Amazon, Google, LinkedIn | H41: Open | J41: Not Started
...
